INFO:werkzeug: * Running on http://127.0.0.1:5000/ (Press CTRL+C to quit)
INFO:sh.command:<Command '/usr/bin/pg_dump -d falcon_db'>: starting process
INFO:sh.command:<Command '/usr/bin/pg_dump -d falcon_db', pid 14400>: process started
INFO:sh.command:<Command '/usr/bin/pg_dump -d falcon_db', pid 14400>: process completed
INFO:root:Start uploading b2b_database_dump
ERROR:root:Traceback (most recent call last):
  File "/home/bohdan/.local/lib/python3.7/site-packages/oauth2client/clientsecrets.py", line 121, in _loadfile
    with open(filename, 'r') as fp:
FileNotFoundError: [Errno 2] No such file or directory: 'client_secrets.json'

During handling of the above exception, another exception occurred:

Traceback (most recent call last):
  File "/usr/local/lib/python3.7/dist-packages/pydrive/auth.py", line 386, in LoadClientConfigFile
    client_type, client_info = clientsecrets.loadfile(client_config_file)
  File "/home/bohdan/.local/lib/python3.7/site-packages/oauth2client/clientsecrets.py", line 165, in loadfile
    return _loadfile(filename)
  File "/home/bohdan/.local/lib/python3.7/site-packages/oauth2client/clientsecrets.py", line 125, in _loadfile
    exc.strerror, exc.errno)
oauth2client.clientsecrets.InvalidClientSecretsError: ('Error opening file', 'client_secrets.json', 'No such file or directory', 2)

During handling of the above exception, another exception occurred:

Traceback (most recent call last):
  File "/home/bohdan/Projects/b2b_actual/scripts/cloud_backup.py", line 21, in upload
    g_login.LocalWebserverAuth()
  File "/usr/local/lib/python3.7/dist-packages/pydrive/auth.py", line 113, in _decorated
    self.GetFlow()
  File "/usr/local/lib/python3.7/dist-packages/pydrive/auth.py", line 443, in GetFlow
    self.LoadClientConfig()
  File "/usr/local/lib/python3.7/dist-packages/pydrive/auth.py", line 366, in LoadClientConfig
    self.LoadClientConfigFile()
  File "/usr/local/lib/python3.7/dist-packages/pydrive/auth.py", line 388, in LoadClientConfigFile
    raise InvalidConfigError('Invalid client secrets file %s' % error)
pydrive.settings.InvalidConfigError: Invalid client secrets file ('Error opening file', 'client_secrets.json', 'No such file or directory', 2)
Traceback (most recent call last):
  File "/home/bohdan/.local/lib/python3.7/site-packages/oauth2client/clientsecrets.py", line 121, in _loadfile
    with open(filename, 'r') as fp:
FileNotFoundError: [Errno 2] No such file or directory: 'client_secrets.json'

During handling of the above exception, another exception occurred:

Traceback (most recent call last):
  File "/usr/local/lib/python3.7/dist-packages/pydrive/auth.py", line 386, in LoadClientConfigFile
    client_type, client_info = clientsecrets.loadfile(client_config_file)
  File "/home/bohdan/.local/lib/python3.7/site-packages/oauth2client/clientsecrets.py", line 165, in loadfile
    return _loadfile(filename)
  File "/home/bohdan/.local/lib/python3.7/site-packages/oauth2client/clientsecrets.py", line 125, in _loadfile
    exc.strerror, exc.errno)
oauth2client.clientsecrets.InvalidClientSecretsError: ('Error opening file', 'client_secrets.json', 'No such file or directory', 2)

During handling of the above exception, another exception occurred:

Traceback (most recent call last):
  File "/home/bohdan/Projects/b2b_actual/scripts/cloud_backup.py", line 21, in upload
    g_login.LocalWebserverAuth()
  File "/usr/local/lib/python3.7/dist-packages/pydrive/auth.py", line 113, in _decorated
    self.GetFlow()
  File "/usr/local/lib/python3.7/dist-packages/pydrive/auth.py", line 443, in GetFlow
    self.LoadClientConfig()
  File "/usr/local/lib/python3.7/dist-packages/pydrive/auth.py", line 366, in LoadClientConfig
    self.LoadClientConfigFile()
  File "/usr/local/lib/python3.7/dist-packages/pydrive/auth.py", line 388, in LoadClientConfigFile
    raise InvalidConfigError('Invalid client secrets file %s' % error)
pydrive.settings.InvalidConfigError: Invalid client secrets file ('Error opening file', 'client_secrets.json', 'No such file or directory', 2)
INFO:werkzeug: * Running on http://127.0.0.1:5000/ (Press CTRL+C to quit)
INFO:sh.command:<Command '/usr/bin/pg_dump -d falcon_db'>: starting process
INFO:sh.command:<Command '/usr/bin/pg_dump -d falcon_db', pid 14525>: process started
INFO:sh.command:<Command '/usr/bin/pg_dump -d falcon_db', pid 14525>: process completed
INFO:root:Start uploading b2b_database_dump.gz
ERROR:root:Traceback (most recent call last):
  File "/home/bohdan/.local/lib/python3.7/site-packages/oauth2client/clientsecrets.py", line 121, in _loadfile
    with open(filename, 'r') as fp:
FileNotFoundError: [Errno 2] No such file or directory: 'client_secrets.json'

During handling of the above exception, another exception occurred:

Traceback (most recent call last):
  File "/usr/local/lib/python3.7/dist-packages/pydrive/auth.py", line 386, in LoadClientConfigFile
    client_type, client_info = clientsecrets.loadfile(client_config_file)
  File "/home/bohdan/.local/lib/python3.7/site-packages/oauth2client/clientsecrets.py", line 165, in loadfile
    return _loadfile(filename)
  File "/home/bohdan/.local/lib/python3.7/site-packages/oauth2client/clientsecrets.py", line 125, in _loadfile
    exc.strerror, exc.errno)
oauth2client.clientsecrets.InvalidClientSecretsError: ('Error opening file', 'client_secrets.json', 'No such file or directory', 2)

During handling of the above exception, another exception occurred:

Traceback (most recent call last):
  File "/home/bohdan/Projects/b2b_actual/scripts/cloud_backup.py", line 21, in upload
    g_login.LocalWebserverAuth()
  File "/usr/local/lib/python3.7/dist-packages/pydrive/auth.py", line 113, in _decorated
    self.GetFlow()
  File "/usr/local/lib/python3.7/dist-packages/pydrive/auth.py", line 443, in GetFlow
    self.LoadClientConfig()
  File "/usr/local/lib/python3.7/dist-packages/pydrive/auth.py", line 366, in LoadClientConfig
    self.LoadClientConfigFile()
  File "/usr/local/lib/python3.7/dist-packages/pydrive/auth.py", line 388, in LoadClientConfigFile
    raise InvalidConfigError('Invalid client secrets file %s' % error)
pydrive.settings.InvalidConfigError: Invalid client secrets file ('Error opening file', 'client_secrets.json', 'No such file or directory', 2)
Traceback (most recent call last):
  File "/home/bohdan/.local/lib/python3.7/site-packages/oauth2client/clientsecrets.py", line 121, in _loadfile
    with open(filename, 'r') as fp:
FileNotFoundError: [Errno 2] No such file or directory: 'client_secrets.json'

During handling of the above exception, another exception occurred:

Traceback (most recent call last):
  File "/usr/local/lib/python3.7/dist-packages/pydrive/auth.py", line 386, in LoadClientConfigFile
    client_type, client_info = clientsecrets.loadfile(client_config_file)
  File "/home/bohdan/.local/lib/python3.7/site-packages/oauth2client/clientsecrets.py", line 165, in loadfile
    return _loadfile(filename)
  File "/home/bohdan/.local/lib/python3.7/site-packages/oauth2client/clientsecrets.py", line 125, in _loadfile
    exc.strerror, exc.errno)
oauth2client.clientsecrets.InvalidClientSecretsError: ('Error opening file', 'client_secrets.json', 'No such file or directory', 2)

During handling of the above exception, another exception occurred:

Traceback (most recent call last):
  File "/home/bohdan/Projects/b2b_actual/scripts/cloud_backup.py", line 21, in upload
    g_login.LocalWebserverAuth()
  File "/usr/local/lib/python3.7/dist-packages/pydrive/auth.py", line 113, in _decorated
    self.GetFlow()
  File "/usr/local/lib/python3.7/dist-packages/pydrive/auth.py", line 443, in GetFlow
    self.LoadClientConfig()
  File "/usr/local/lib/python3.7/dist-packages/pydrive/auth.py", line 366, in LoadClientConfig
    self.LoadClientConfigFile()
  File "/usr/local/lib/python3.7/dist-packages/pydrive/auth.py", line 388, in LoadClientConfigFile
    raise InvalidConfigError('Invalid client secrets file %s' % error)
pydrive.settings.InvalidConfigError: Invalid client secrets file ('Error opening file', 'client_secrets.json', 'No such file or directory', 2)
